### 에러핸들링

---

- #### 비동기통신


|명칭|에러 핸들링|
|--|--|
|Promise|1. Promise.catch() <br>2. Promise.then(() => { // 이행(fulfilled)}, (e) => { // reject(에러처리)})|
|async await|try...catch<br>try...catch는 동기적으로 작동하고, async는 함수를 비동기로 만들지만, await은 함수를 동기코드로 변경한다. 그렇기 때문에 try...catch를 사용할 수 있다.|

- ##### Promise
    - 에러핸들링을 위해 catch 메소드를 사용한다.
    - then의 두번째 인자인 onRejected를 사용한다.
    - await 키워드를 사용해서 동기 코드로 변경한다.

- ##### async await
    - async 내에서 await 예외가 발생하면 throw 반환한다.
    - then의 두번째 인자인 onRejected를 사용한다.
    - await 키워드를 사용해서 동기 코드로 변경한다.

---

- ##### try catch
  - <span style="color: red;">try...catch는</span> <span style="font-size: 1.3rem; font-weight: bold;">동기적으로 작동</span>하기 때문에 <span style="color: red; font-size: 1.3rem; font-weight: bold;">비동기 오류를 처리하기에는 적합하지 않다.</span>

  ```jsx

  // setTimeout은 전형적인 비동기 함수이다. 
  // 콜백큐에 콜백을 예약하기 때문에 try...cartch 블록에서 분리해야 한다.

  // (1) - 잘못된 예시
  try {
    setTimeout(() => {
      throw new Error("err");
    }, 200);
  } catch (err) {
    console.log(err);
  }

  // (1) - 수정 예시
  new Promise((resolve, reject) => {
    setTimeout(() => {
      try {
        throw new Error("err");
      } catch (err) {
        reject(err);
      }
    }, 200);
  })
  .then((res) => {
    console.log(`성공 : ${res}`);
  })
  .catch((err) => {
    console.log(`실패 : ${err}`);
  })
  ```

  ```jsx
  // (2) - 잘못된 예시
  try {
    Promise.resolve().then(() => {
      throw new Error("err");
    })
  } catch (err) {
    console.log(err);
  }

  // (2) - 수정 예시
  async function timeOut(ms) {
    return new Promise((resolve, reject) => setTimeout(() => {
      resolve();
      //reject();
    }, ms))
    .then((res) => {
      return `성공 : ${res}`;
    })
    .catch((err) => {
      return `실패 : ${err}`;
    });
  }

  async function init() {
    try {
      const result = await timeOut(200);
      console.log(result);
    } catch (err) {
      console.log(err);
    }
  }

  init()
  ```
