### 에러핸들링

---

- ##### try catch
  - <span style="color: red;">try...catch는</span> <span style="font-size: 1.3rem; font-weight: bold;">동기적으로 작동</span>하기 때문에 <span style="color: red; font-size: 1.3rem; font-weight: bold;">비동기 오류를 처리하기에는 적합하지 않다.</span>

  ```jsx

  // setTimeout은 전형적인 비동기 함수이다. 
  // 이벤트 큐에 콜백을 예약하기 때문에 try...cartch 블록에서 분리해야 한다.

  // (1) - 잘못된 예시
  try {
    setTimeout(() => {
      throw new Error("err");
    }, 200);
  } catch (err) {
    console.log(err);
  }

  // (1) - 수정 예시
  new Promise((resolve, reject) => {
    setTimeout(() => {
      try {
        throw new Error("err");
      } catch (err) {
        reject(err);
      }
    }, 200);
  })
  .then((res) => {
    console.log(`성공 : ${res}`);
  })
  .catch((err) => {
    console.log(`실패 : ${err}`);
  })


  // (2) - 잘못된 예시
  try {
    Promise.resolve().then(() => {
      throw new Error("err");
    })
  } catch (err) {
    console.log(err);
  }

  // (2) - 수정 예시
  async function timeOut(ms) {
    return new Promise((resolve, reject) => setTimeout(() => {
      resolve();
      //reject();
    }, ms))
    .then((res) => {
      return `성공 : ${res}`;
    })
    .catch((err) => {
      return `실패 : ${err}`;
    });
  }

  async function init() {
    try {
      const result = await timeOut(200);
      console.log(result);
    } catch (err) {
      console.log(err);
    }
  }

  init()

  ```
